Workbook

Sheet IO Summary
A1: Gulf Shores 36542 — Investor I/O Ratio Summary
A2: I/O Ratio = NOI ÷ Annual Cash Inputs | NOI = Gross Revenue − Annual Cash Inputs | Illustrative 2026 base case (not an appraisal)
A3: Market context: median sold ~$450K (condo+SFH mix); VR mgmt fees often 20–35% of gross; carrying costs include wind/flood, HOA, furnishings reserves.
A5: Scenario | B5: Purchase Price | C5: Annual Cash Inputs | D5: Gross Revenue | E5: NOI | F5: I/O Ratio (NOI÷Inputs) | G5: Cap Rate (NOI÷Purchase) | H5: Notes
A6: 1BR condo | B6: 275000 | C6: 27688 | D6: 32375 | E6: 4688 | F6: 0.16930023 | G6: 0.017045455 | H6: West Beach / mid-rise studio-1BR; softer ADR off-peak
A7: 2BR gulf-view | B7: 425000 | C7: 39028 | D7: 51675 | E7: 12648 | F7: 0.32406636 | G7: 0.029758824 | H7: Indirect / side gulf-view; near median sold ~$450K
A8: 2BR gulf-front | B8: 575000 | C8: 50410 | D8: 72450 | E8: 22040 | F8: 0.43721484 | G8: 0.038330435 | H8: Direct gulf-front tower (Crystal / Seawind / Lighthouse class)
A9: 3BR gulf-front | B9: 750000 | C9: 66298 | D9: 97825 | E9: 31528 | F9: 0.47554584 | G9: 0.042036667 | H9: Larger gulf-front lockout / 3BR premium
A10: 4BR house | B10: 895000 | C10: 67968 | D10: 98975 | E10: 31008 | F10: 0.45621069 | G10: 0.034645251 | H10: Canal / near-beach SFH; higher insurance & maint, no HOA
A12: Definition
A13: Annual Cash Inputs | B13: Sum of: property-mgmt fees + platform/OTA fees + HOA + insurance (wind/flood/HO) + owner utilities + maintenance/turnover + FF&E reserves + property tax. Excludes purchase price / debt principal.
A14: I/O Ratio | B14: NOI ÷ Annual Cash Inputs. Values > 1.0 mean every $1 of annual carrying cash returns more than $1 of NOI; < 1.0 means inputs exceed residual NOI (still may be strategic for appreciation / personal use).
A15: How to edit | B15: Change yellow driver cells on the Unit Economics sheet; Summary figures above are base-case snapshots. Sensitivity / Manager Fee Impact sheets stress-test the 2BR gulf-front case.

Sheet Unit Economics
A1: Unit Economics — Editable Drivers (yellow) + Formulas (green)
A2: I/O Ratio = NOI ÷ Annual Cash Inputs. Cash-on-cash assumes illustrative down-payment % (row Equity %). Edit yellow cells only.
A4: DRIVER / METRIC | B4: 1BR condo | C4: 2BR gulf-view | D4: 2BR gulf-front | E4: 3BR gulf-front | F4: 4BR house
A5: Purchase Price ($) | B5: 275000 | C5: 425000 | D5: 575000 | E5: 750000 | F5: 895000
A6: ADR — Avg Daily Rate ($) | B6: 185 | C6: 265 | D6: 345 | E6: 455 | F6: 535
A7: Occupied Nights / Year | B7: 175 | C7: 195 | D7: 210 | E7: 215 | F7: 185
A8: Property Mgmt Fee % | B8: 0.25 | C8: 0.25 | D8: 0.25 | E8: 0.25 | F8: 0.25
A9: Platform / OTA Fee % | B9: 0.05 | C9: 0.05 | D9: 0.05 | E9: 0.05 | F9: 0.05
A10: HOA / Condo Dues ($/yr) | B10: 6200 | C10: 7800 | D10: 9600 | E10: 12500 | F10: 0
A11: Insurance ($/yr) | B11: 3200 | C11: 4200 | D11: 5200 | E11: 6500 | F11: 14500
A12: Utilities — owner ($/yr) | B12: 2400 | C12: 3000 | D12: 3300 | E12: 4200 | F12: 4800
A13: Maintenance / Turnover ($/yr) | B13: 2800 | C13: 3600 | D13: 4200 | E13: 5500 | F13: 8500
A14: FF&E / CapEx Reserves ($/yr) | B14: 2000 | C14: 2800 | D14: 3500 | E14: 4500 | F14: 6000
A15: Property Tax ($/yr) | B15: 1375 | C15: 2125 | D15: 2875 | E15: 3750 | F15: 4475
A16: Illustrative Equity / Down % | B16: 0.25 | C16: 0.25 | D16: 0.25 | E16: 0.25 | F16: 0.25
A18: COMPUTED (Excel formulas — do not overwrite)
A19: Gross Revenue ($) | B19: =B6*B7 | C19: =C6*C7 | D19: =D6*D7 | E19: =E6*E7 | F19: =F6*F7
A20: Platform Fees ($) | B20: =B19*B9 | C20: =C19*C9 | D20: =D19*D9 | E20: =E19*E9 | F20: =F19*F9
A21: Mgmt Fees ($) | B21: =B19*B8 | C21: =C19*C8 | D21: =D19*D8 | E21: =E19*E8 | F21: =F19*F8
A22: Annual Cash Inputs ($) | B22: =B21+B20+B10+B11+B12+B13+B14+B15 | C22: =C21+C20+C10+C11+C12+C13+C14+C15 | D22: =D21+D20+D10+D11+D12+D13+D14+D15 | E22: =E21+E20+E10+E11+E12+E13+E14+E15 | F22: =F21+F20+F10+F11+F12+F13+F14+F15
A23: NOI ($) | B23: =B19-B22 | C23: =C19-C22 | D23: =D19-D22 | E23: =E19-E22 | F23: =F19-F22
A24: I/O Ratio (NOI÷Inputs) | B24: =IF(B22=0,"n/a",B23/B22) | C24: =IF(C22=0,"n/a",C23/C22) | D24: =IF(D22=0,"n/a",D23/D22) | E24: =IF(E22=0,"n/a",E23/E22) | F24: =IF(F22=0,"n/a",F23/F22)
A25: Cap Rate (NOI÷Purchase) | B25: =IF(B5=0,"n/a",B23/B5) | C25: =IF(C5=0,"n/a",C23/C5) | D25: =IF(D5=0,"n/a",D23/D5) | E25: =IF(E5=0,"n/a",E23/E5) | F25: =IF(F5=0,"n/a",F23/F5)
A26: Cash-on-Cash (NOI÷Equity) | B26: =IF(B5*B16=0,"n/a",B23/(B5*B16)) | C26: =IF(C5*C16=0,"n/a",C23/(C5*C16)) | D26: =IF(D5*D16=0,"n/a",D23/(D5*D16)) | E26: =IF(E5*E16=0,"n/a",E23/(E5*E16)) | F26: =IF(F5*F16=0,"n/a",F23/(F5*F16))
A27: Gross Yield (Gross÷Purchase) | B27: =IF(B5=0,"n/a",B19/B5) | C27: =IF(C5=0,"n/a",C19/C5) | D27: =IF(D5=0,"n/a",D19/D5) | E27: =IF(E5=0,"n/a",E19/E5) | F27: =IF(F5=0,"n/a",F19/F5)
A28: Payback Years (Purchase÷NOI) | B28: =IF(B23<=0,"n/a",B5/B23) | C28: =IF(C23<=0,"n/a",C5/C23) | D28: =IF(D23<=0,"n/a",D5/D23) | E28: =IF(E23<=0,"n/a",E5/E23) | F28: =IF(F23<=0,"n/a",F5/F23)
A30: Legend: Yellow = editable drivers | Green = formula outputs | Cash-on-cash ignores debt service (equity multiple only).

Sheet Sensitivity
A1: Sensitivity — 2BR Gulf-Front (base from Unit Economics column D)
A2: Grids use FIXED annual fixed costs + fee % from Unit Economics!D (2BR gulf-front). Vary ADR (rows) × Occupied Nights (cols).
A4: Linked drivers (from Unit Economics!D)
A5: Mgmt % | B5: ='Unit Economics'!D8 | C5: Platform % | D5: ='Unit Economics'!D9 | E5: Fixed OpEx $/yr | F5: ='Unit Economics'!D10+'Unit Economics'!D11+'Unit Economics'!D12+'Unit Economics'!D13+'Unit Economics'!D14+'Unit Economics'!D15 | G5: Purchase | H5: ='Unit Economics'!D5
A7: NOI ($) — ADR × Occupied Nights
A8: ADR \ Nights | B8: 150 | C8: 170 | D8: 190 | E8: 210 | F8: 230 | G8: 250 | H8: 270
A9: 250 | B9: =$A9*B$8*(1-$B$5-$D$5)-$F$5 | C9: =$A9*C$8*(1-$B$5-$D$5)-$F$5 | D9: =$A9*D$8*(1-$B$5-$D$5)-$F$5 | E9: =$A9*E$8*(1-$B$5-$D$5)-$F$5 | F9: =$A9*F$8*(1-$B$5-$D$5)-$F$5 | G9: =$A9*G$8*(1-$B$5-$D$5)-$F$5 | H9: =$A9*H$8*(1-$B$5-$D$5)-$F$5
A10: 275 | B10: =$A10*B$8*(1-$B$5-$D$5)-$F$5 | C10: =$A10*C$8*(1-$B$5-$D$5)-$F$5 | D10: =$A10*D$8*(1-$B$5-$D$5)-$F$5 | E10: =$A10*E$8*(1-$B$5-$D$5)-$F$5 | F10: =$A10*F$8*(1-$B$5-$D$5)-$F$5 | G10: =$A10*G$8*(1-$B$5-$D$5)-$F$5 | H10: =$A10*H$8*(1-$B$5-$D$5)-$F$5
A11: 300 | B11: =$A11*B$8*(1-$B$5-$D$5)-$F$5 | C11: =$A11*C$8*(1-$B$5-$D$5)-$F$5 | D11: =$A11*D$8*(1-$B$5-$D$5)-$F$5 | E11: =$A11*E$8*(1-$B$5-$D$5)-$F$5 | F11: =$A11*F$8*(1-$B$5-$D$5)-$F$5 | G11: =$A11*G$8*(1-$B$5-$D$5)-$F$5 | H11: =$A11*H$8*(1-$B$5-$D$5)-$F$5
A12: 325 | B12: =$A12*B$8*(1-$B$5-$D$5)-$F$5 | C12: =$A12*C$8*(1-$B$5-$D$5)-$F$5 | D12: =$A12*D$8*(1-$B$5-$D$5)-$F$5 | E12: =$A12*E$8*(1-$B$5-$D$5)-$F$5 | F12: =$A12*F$8*(1-$B$5-$D$5)-$F$5 | G12: =$A12*G$8*(1-$B$5-$D$5)-$F$5 | H12: =$A12*H$8*(1-$B$5-$D$5)-$F$5
A13: 345 | B13: =$A13*B$8*(1-$B$5-$D$5)-$F$5 | C13: =$A13*C$8*(1-$B$5-$D$5)-$F$5 | D13: =$A13*D$8*(1-$B$5-$D$5)-$F$5 | E13: =$A13*E$8*(1-$B$5-$D$5)-$F$5 | F13: =$A13*F$8*(1-$B$5-$D$5)-$F$5 | G13: =$A13*G$8*(1-$B$5-$D$5)-$F$5 | H13: =$A13*H$8*(1-$B$5-$D$5)-$F$5
A14: 375 | B14: =$A14*B$8*(1-$B$5-$D$5)-$F$5 | C14: =$A14*C$8*(1-$B$5-$D$5)-$F$5 | D14: =$A14*D$8*(1-$B$5-$D$5)-$F$5 | E14: =$A14*E$8*(1-$B$5-$D$5)-$F$5 | F14: =$A14*F$8*(1-$B$5-$D$5)-$F$5 | G14: =$A14*G$8*(1-$B$5-$D$5)-$F$5 | H14: =$A14*H$8*(1-$B$5-$D$5)-$F$5
A15: 400 | B15: =$A15*B$8*(1-$B$5-$D$5)-$F$5 | C15: =$A15*C$8*(1-$B$5-$D$5)-$F$5 | D15: =$A15*D$8*(1-$B$5-$D$5)-$F$5 | E15: =$A15*E$8*(1-$B$5-$D$5)-$F$5 | F15: =$A15*F$8*(1-$B$5-$D$5)-$F$5 | G15: =$A15*G$8*(1-$B$5-$D$5)-$F$5 | H15: =$A15*H$8*(1-$B$5-$D$5)-$F$5
A16: 425 | B16: =$A16*B$8*(1-$B$5-$D$5)-$F$5 | C16: =$A16*C$8*(1-$B$5-$D$5)-$F$5 | D16: =$A16*D$8*(1-$B$5-$D$5)-$F$5 | E16: =$A16*E$8*(1-$B$5-$D$5)-$F$5 | F16: =$A16*F$8*(1-$B$5-$D$5)-$F$5 | G16: =$A16*G$8*(1-$B$5-$D$5)-$F$5 | H16: =$A16*H$8*(1-$B$5-$D$5)-$F$5
A17: 450 | B17: =$A17*B$8*(1-$B$5-$D$5)-$F$5 | C17: =$A17*C$8*(1-$B$5-$D$5)-$F$5 | D17: =$A17*D$8*(1-$B$5-$D$5)-$F$5 | E17: =$A17*E$8*(1-$B$5-$D$5)-$F$5 | F17: =$A17*F$8*(1-$B$5-$D$5)-$F$5 | G17: =$A17*G$8*(1-$B$5-$D$5)-$F$5 | H17: =$A17*H$8*(1-$B$5-$D$5)-$F$5
A20: I/O Ratio (NOI÷Inputs) — ADR × Occupied Nights
A21: ADR \ Nights | B21: 150 | C21: 170 | D21: 190 | E21: 210 | F21: 230 | G21: 250 | H21: 270
A22: 250 | B22: =IF(($A22*B$21*($B$5+$D$5)+$F$5)=0,"n/a",($A22*B$21*(1-$B$5-$D$5)-$F$5)/($A22*B$21*($B$5+$D$5)+$F$5)) | C22: =IF(($A22*C$21*($B$5+$D$5)+$F$5)=0,"n/a",($A22*C$21*(1-$B$5-$D$5)-$F$5)/($A22*C$21*($B$5+$D$5)+$F$5)) | D22: =IF(($A22*D$21*($B$5+$D$5)+$F$5)=0,"n/a",($A22*D$21*(1-$B$5-$D$5)-$F$5)/($A22*D$21*($B$5+$D$5)+$F$5)) | E22: =IF(($A22*E$21*($B$5+$D$5)+$F$5)=0,"n/a",($A22*E$21*(1-$B$5-$D$5)-$F$5)/($A22*E$21*($B$5+$D$5)+$F$5)) | F22: =IF(($A22*F$21*($B$5+$D$5)+$F$5)=0,"n/a",($A22*F$21*(1-$B$5-$D$5)-$F$5)/($A22*F$21*($B$5+$D$5)+$F$5)) | G22: =IF(($A22*G$21*($B$5+$D$5)+$F$5)=0,"n/a",($A22*G$21*(1-$B$5-$D$5)-$F$5)/($A22*G$21*($B$5+$D$5)+$F$5)) | H22: =IF(($A22*H$21*($B$5+$D$5)+$F$5)=0,"n/a",($A22*H$21*(1-$B$5-$D$5)-$F$5)/($A22*H$21*($B$5+$D$5)+$F$5))
A23: 275 | B23: =IF(($A23*B$21*($B$5+$D$5)+$F$5)=0,"n/a",($A23*B$21*(1-$B$5-$D$5)-$F$5)/($A23*B$21*($B$5+$D$5)+$F$5)) | C23: =IF(($A23*C$21*($B$5+$D$5)+$F$5)=0,"n/a",($A23*C$21*(1-$B$5-$D$5)-$F$5)/($A23*C$21*($B$5+$D$5)+$F$5)) | D23: =IF(($A23*D$21*($B$5+$D$5)+$F$5)=0,"n/a",($A23*D$21*(1-$B$5-$D$5)-$F$5)/($A23*D$21*($B$5+$D$5)+$F$5)) | E23: =IF(($A23*E$21*($B$5+$D$5)+$F$5)=0,"n/a",($A23*E$21*(1-$B$5-$D$5)-$F$5)/($A23*E$21*($B$5+$D$5)+$F$5)) | F23: =IF(($A23*F$21*($B$5+$D$5)+$F$5)=0,"n/a",($A23*F$21*(1-$B$5-$D$5)-$F$5)/($A23*F$21*($B$5+$D$5)+$F$5)) | G23: =IF(($A23*G$21*($B$5+$D$5)+$F$5)=0,"n/a",($A23*G$21*(1-$B$5-$D$5)-$F$5)/($A23*G$21*($B$5+$D$5)+$F$5)) | H23: =IF(($A23*H$21*($B$5+$D$5)+$F$5)=0,"n/a",($A23*H$21*(1-$B$5-$D$5)-$F$5)/($A23*H$21*($B$5+$D$5)+$F$5))
A24: 300 | B24: =IF(($A24*B$21*($B$5+$D$5)+$F$5)=0,"n/a",($A24*B$21*(1-$B$5-$D$5)-$F$5)/($A24*B$21*($B$5+$D$5)+$F$5)) | C24: =IF(($A24*C$21*($B$5+$D$5)+$F$5)=0,"n/a",($A24*C$21*(1-$B$5-$D$5)-$F$5)/($A24*C$21*($B$5+$D$5)+$F$5)) | D24: =IF(($A24*D$21*($B$5+$D$5)+$F$5)=0,"n/a",($A24*D$21*(1-$B$5-$D$5)-$F$5)/($A24*D$21*($B$5+$D$5)+$F$5)) | E24: =IF(($A24*E$21*($B$5+$D$5)+$F$5)=0,"n/a",($A24*E$21*(1-$B$5-$D$5)-$F$5)/($A24*E$21*($B$5+$D$5)+$F$5)) | F24: =IF(($A24*F$21*($B$5+$D$5)+$F$5)=0,"n/a",($A24*F$21*(1-$B$5-$D$5)-$F$5)/($A24*F$21*($B$5+$D$5)+$F$5)) | G24: =IF(($A24*G$21*($B$5+$D$5)+$F$5)=0,"n/a",($A24*G$21*(1-$B$5-$D$5)-$F$5)/($A24*G$21*($B$5+$D$5)+$F$5)) | H24: =IF(($A24*H$21*($B$5+$D$5)+$F$5)=0,"n/a",($A24*H$21*(1-$B$5-$D$5)-$F$5)/($A24*H$21*($B$5+$D$5)+$F$5))
A25: 325 | B25: =IF(($A25*B$21*($B$5+$D$5)+$F$5)=0,"n/a",($A25*B$21*(1-$B$5-$D$5)-$F$5)/($A25*B$21*($B$5+$D$5)+$F$5)) | C25: =IF(($A25*C$21*($B$5+$D$5)+$F$5)=0,"n/a",($A25*C$21*(1-$B$5-$D$5)-$F$5)/($A25*C$21*($B$5+$D$5)+$F$5)) | D25: =IF(($A25*D$21*($B$5+$D$5)+$F$5)=0,"n/a",($A25*D$21*(1-$B$5-$D$5)-$F$5)/($A25*D$21*($B$5+$D$5)+$F$5)) | E25: =IF(($A25*E$21*($B$5+$D$5)+$F$5)=0,"n/a",($A25*E$21*(1-$B$5-$D$5)-$F$5)/($A25*E$21*($B$5+$D$5)+$F$5)) | F25: =IF(($A25*F$21*($B$5+$D$5)+$F$5)=0,"n/a",($A25*F$21*(1-$B$5-$D$5)-$F$5)/($A25*F$21*($B$5+$D$5)+$F$5)) | G25: =IF(($A25*G$21*($B$5+$D$5)+$F$5)=0,"n/a",($A25*G$21*(1-$B$5-$D$5)-$F$5)/($A25*G$21*($B$5+$D$5)+$F$5)) | H25: =IF(($A25*H$21*($B$5+$D$5)+$F$5)=0,"n/a",($A25*H$21*(1-$B$5-$D$5)-$F$5)/($A25*H$21*($B$5+$D$5)+$F$5))
A26: 345 | B26: =IF(($A26*B$21*($B$5+$D$5)+$F$5)=0,"n/a",($A26*B$21*(1-$B$5-$D$5)-$F$5)/($A26*B$21*($B$5+$D$5)+$F$5)) | C26: =IF(($A26*C$21*($B$5+$D$5)+$F$5)=0,"n/a",($A26*C$21*(1-$B$5-$D$5)-$F$5)/($A26*C$21*($B$5+$D$5)+$F$5)) | D26: =IF(($A26*D$21*($B$5+$D$5)+$F$5)=0,"n/a",($A26*D$21*(1-$B$5-$D$5)-$F$5)/($A26*D$21*($B$5+$D$5)+$F$5)) | E26: =IF(($A26*E$21*($B$5+$D$5)+$F$5)=0,"n/a",($A26*E$21*(1-$B$5-$D$5)-$F$5)/($A26*E$21*($B$5+$D$5)+$F$5)) | F26: =IF(($A26*F$21*($B$5+$D$5)+$F$5)=0,"n/a",($A26*F$21*(1-$B$5-$D$5)-$F$5)/($A26*F$21*($B$5+$D$5)+$F$5)) | G26: =IF(($A26*G$21*($B$5+$D$5)+$F$5)=0,"n/a",($A26*G$21*(1-$B$5-$D$5)-$F$5)/($A26*G$21*($B$5+$D$5)+$F$5)) | H26: =IF(($A26*H$21*($B$5+$D$5)+$F$5)=0,"n/a",($A26*H$21*(1-$B$5-$D$5)-$F$5)/($A26*H$21*($B$5+$D$5)+$F$5))
A27: 375 | B27: =IF(($A27*B$21*($B$5+$D$5)+$F$5)=0,"n/a",($A27*B$21*(1-$B$5-$D$5)-$F$5)/($A27*B$21*($B$5+$D$5)+$F$5)) | C27: =IF(($A27*C$21*($B$5+$D$5)+$F$5)=0,"n/a",($A27*C$21*(1-$B$5-$D$5)-$F$5)/($A27*C$21*($B$5+$D$5)+$F$5)) | D27: =IF(($A27*D$21*($B$5+$D$5)+$F$5)=0,"n/a",($A27*D$21*(1-$B$5-$D$5)-$F$5)/($A27*D$21*($B$5+$D$5)+$F$5)) | E27: =IF(($A27*E$21*($B$5+$D$5)+$F$5)=0,"n/a",($A27*E$21*(1-$B$5-$D$5)-$F$5)/($A27*E$21*($B$5+$D$5)+$F$5)) | F27: =IF(($A27*F$21*($B$5+$D$5)+$F$5)=0,"n/a",($A27*F$21*(1-$B$5-$D$5)-$F$5)/($A27*F$21*($B$5+$D$5)+$F$5)) | G27: =IF(($A27*G$21*($B$5+$D$5)+$F$5)=0,"n/a",($A27*G$21*(1-$B$5-$D$5)-$F$5)/($A27*G$21*($B$5+$D$5)+$F$5)) | H27: =IF(($A27*H$21*($B$5+$D$5)+$F$5)=0,"n/a",($A27*H$21*(1-$B$5-$D$5)-$F$5)/($A27*H$21*($B$5+$D$5)+$F$5))
A28: 400 | B28: =IF(($A28*B$21*($B$5+$D$5)+$F$5)=0,"n/a",($A28*B$21*(1-$B$5-$D$5)-$F$5)/($A28*B$21*($B$5+$D$5)+$F$5)) | C28: =IF(($A28*C$21*($B$5+$D$5)+$F$5)=0,"n/a",($A28*C$21*(1-$B$5-$D$5)-$F$5)/($A28*C$21*($B$5+$D$5)+$F$5)) | D28: =IF(($A28*D$21*($B$5+$D$5)+$F$5)=0,"n/a",($A28*D$21*(1-$B$5-$D$5)-$F$5)/($A28*D$21*($B$5+$D$5)+$F$5)) | E28: =IF(($A28*E$21*($B$5+$D$5)+$F$5)=0,"n/a",($A28*E$21*(1-$B$5-$D$5)-$F$5)/($A28*E$21*($B$5+$D$5)+$F$5)) | F28: =IF(($A28*F$21*($B$5+$D$5)+$F$5)=0,"n/a",($A28*F$21*(1-$B$5-$D$5)-$F$5)/($A28*F$21*($B$5+$D$5)+$F$5)) | G28: =IF(($A28*G$21*($B$5+$D$5)+$F$5)=0,"n/a",($A28*G$21*(1-$B$5-$D$5)-$F$5)/($A28*G$21*($B$5+$D$5)+$F$5)) | H28: =IF(($A28*H$21*($B$5+$D$5)+$F$5)=0,"n/a",($A28*H$21*(1-$B$5-$D$5)-$F$5)/($A28*H$21*($B$5+$D$5)+$F$5))
A29: 425 | B29: =IF(($A29*B$21*($B$5+$D$5)+$F$5)=0,"n/a",($A29*B$21*(1-$B$5-$D$5)-$F$5)/($A29*B$21*($B$5+$D$5)+$F$5)) | C29: =IF(($A29*C$21*($B$5+$D$5)+$F$5)=0,"n/a",($A29*C$21*(1-$B$5-$D$5)-$F$5)/($A29*C$21*($B$5+$D$5)+$F$5)) | D29: =IF(($A29*D$21*($B$5+$D$5)+$F$5)=0,"n/a",($A29*D$21*(1-$B$5-$D$5)-$F$5)/($A29*D$21*($B$5+$D$5)+$F$5)) | E29: =IF(($A29*E$21*($B$5+$D$5)+$F$5)=0,"n/a",($A29*E$21*(1-$B$5-$D$5)-$F$5)/($A29*E$21*($B$5+$D$5)+$F$5)) | F29: =IF(($A29*F$21*($B$5+$D$5)+$F$5)=0,"n/a",($A29*F$21*(1-$B$5-$D$5)-$F$5)/($A29*F$21*($B$5+$D$5)+$F$5)) | G29: =IF(($A29*G$21*($B$5+$D$5)+$F$5)=0,"n/a",($A29*G$21*(1-$B$5-$D$5)-$F$5)/($A29*G$21*($B$5+$D$5)+$F$5)) | H29: =IF(($A29*H$21*($B$5+$D$5)+$F$5)=0,"n/a",($A29*H$21*(1-$B$5-$D$5)-$F$5)/($A29*H$21*($B$5+$D$5)+$F$5))
A30: 450 | B30: =IF(($A30*B$21*($B$5+$D$5)+$F$5)=0,"n/a",($A30*B$21*(1-$B$5-$D$5)-$F$5)/($A30*B$21*($B$5+$D$5)+$F$5)) | C30: =IF(($A30*C$21*($B$5+$D$5)+$F$5)=0,"n/a",($A30*C$21*(1-$B$5-$D$5)-$F$5)/($A30*C$21*($B$5+$D$5)+$F$5)) | D30: =IF(($A30*D$21*($B$5+$D$5)+$F$5)=0,"n/a",($A30*D$21*(1-$B$5-$D$5)-$F$5)/($A30*D$21*($B$5+$D$5)+$F$5)) | E30: =IF(($A30*E$21*($B$5+$D$5)+$F$5)=0,"n/a",($A30*E$21*(1-$B$5-$D$5)-$F$5)/($A30*E$21*($B$5+$D$5)+$F$5)) | F30: =IF(($A30*F$21*($B$5+$D$5)+$F$5)=0,"n/a",($A30*F$21*(1-$B$5-$D$5)-$F$5)/($A30*F$21*($B$5+$D$5)+$F$5)) | G30: =IF(($A30*G$21*($B$5+$D$5)+$F$5)=0,"n/a",($A30*G$21*(1-$B$5-$D$5)-$F$5)/($A30*G$21*($B$5+$D$5)+$F$5)) | H30: =IF(($A30*H$21*($B$5+$D$5)+$F$5)=0,"n/a",($A30*H$21*(1-$B$5-$D$5)-$F$5)/($A30*H$21*($B$5+$D$5)+$F$5))
A32: Base case marker: ADR $345 × 210 nights (Unit Economics 2BR gulf-front). Green = stronger; red = weaker.

Sheet Manager Fee Impact
A1: Manager Fee Impact on I/O — Fixed Gross (2BR gulf-front base)
A2: Gross held constant at Unit Economics 2BR gulf-front (ADR×nights). Sweep property-mgmt fee 15%–35%. Platform % and fixed OpEx remain linked.
A4: Fixed Gross Revenue | B4: ='Unit Economics'!D19 | C4: Platform % | D4: ='Unit Economics'!D9 | E4: Fixed OpEx (excl. mgmt & platform) | F4: ='Unit Economics'!D10+'Unit Economics'!D11+'Unit Economics'!D12+'Unit Economics'!D13+'Unit Economics'!D14+'Unit Economics'!D15
A6: Mgmt Fee % | B6: Mgmt Fees $ | C6: Platform Fees $ | D6: Annual Cash Inputs $ | E6: NOI $ | F6: I/O Ratio | G6: Δ I/O vs 25% base
A7: 0.15 | B7: =$B$4*A7 | C7: =$B$4*$D$4 | D7: =B7+C7+$F$4 | E7: =$B$4-D7 | F7: =IF(D7=0,"n/a",E7/D7) | G7: =F7-F11
A8: 0.18 | B8: =$B$4*A8 | C8: =$B$4*$D$4 | D8: =B8+C8+$F$4 | E8: =$B$4-D8 | F8: =IF(D8=0,"n/a",E8/D8) | G8: =F8-F11
A9: 0.2 | B9: =$B$4*A9 | C9: =$B$4*$D$4 | D9: =B9+C9+$F$4 | E9: =$B$4-D9 | F9: =IF(D9=0,"n/a",E9/D9) | G9: =F9-F11
A10: 0.22 | B10: =$B$4*A10 | C10: =$B$4*$D$4 | D10: =B10+C10+$F$4 | E10: =$B$4-D10 | F10: =IF(D10=0,"n/a",E10/D10) | G10: =F10-F11
A11: 0.25 | B11: =$B$4*A11 | C11: =$B$4*$D$4 | D11: =B11+C11+$F$4 | E11: =$B$4-D11 | F11: =IF(D11=0,"n/a",E11/D11) | G11: =F11-F11
A12: 0.28 | B12: =$B$4*A12 | C12: =$B$4*$D$4 | D12: =B12+C12+$F$4 | E12: =$B$4-D12 | F12: =IF(D12=0,"n/a",E12/D12) | G12: =F12-F11
A13: 0.3 | B13: =$B$4*A13 | C13: =$B$4*$D$4 | D13: =B13+C13+$F$4 | E13: =$B$4-D13 | F13: =IF(D13=0,"n/a",E13/D13) | G13: =F13-F11
A14: 0.32 | B14: =$B$4*A14 | C14: =$B$4*$D$4 | D14: =B14+C14+$F$4 | E14: =$B$4-D14 | F14: =IF(D14=0,"n/a",E14/D14) | G14: =F14-F11
A15: 0.35 | B15: =$B$4*A15 | C15: =$B$4*$D$4 | D15: =B15+C15+$F$4 | E15: =$B$4-D15 | F15: =IF(D15=0,"n/a",E15/D15) | G15: =F15-F11
A18: Market note: Gulf Shores VR management commonly quoted ~20–35% of gross (see MARKET_GULF_SHORES_36542.md). Lower fees improve I/O but may trade service / occupancy.

Sheet Inventory Scale
A1: Inventory Scale — rentals_36542.json (463 records) + Illustrative Portfolio I/O
A2: Public scrape best-effort (2026-09-05). Manager coast-wide claims >> ZIP-only inventory. Deduplicated by type + name; beds often unknown at unit level.
A4: Record counts by type
A5: Type | B5: Count
A6: condo_unit | B6: 285
A7: condo_complex | B7: 100
A8: house | B8: 71
A9: manager_portfolio | B9: 7
A10: TOTAL | B10: 463
A12: Classified unit/house buckets (where beds / gulf-front known)
A13: Class | B13: Count | C13: Maps to scenario
A14: 1BR_condo | B14: 5 | C14: 1BR condo
A15: 2BR_gulf_front_condo | B15: 26 | C15: 2BR gulf-front
A16: 2BR_condo_view_or_unk | B16: 8 | C16: 2BR gulf-view (approx)
A17: 2BR_non_front_condo | B17: 6 | C17: 2BR gulf-view / inland
A18: 3BR_gulf_front_condo | B18: 27 | C18: 3BR gulf-front
A19: 3BR_condo_other | B19: 2 | C19: 3BR other
A20: 4BR+_condo | B20: 4 | C20: 4BR+ condo
A21: 4BR+_house | B21: 14 | C21: 4BR house
A22: 3BR_house | B22: 15 | C22: —
A23: 2BR_house | B23: 9 | C23: —
A24: house_other | B24: 33 | C24: —
A25: condo_unit_gulf_front_beds_unk | B25: 194 | C25: beds unknown (gulf-front)
... A29: manager_portfolio | B29: 7 | C29: manager rollups
A32: Manager portfolio notes (from JSON)
A33: Manager | B33: Notes / public claims | C33: Source URL
A34: Beachball Properties | B34: Public claim grown to 300+ properties coast-wide; Gulf Shores vacation rentals page shows 157 properties in filtered view (includes duplexes/homes/condos). | C34: https://beachball.com/gulf-shores-vacation-rentals/
A35: Brett/Robinson Vacation Rentals | B35: Public claim 1,800+ vacation rental units coast-wide; Phoenix Gulf Shores, Phoenix Gulf Shores II, Phoenix All Suites, Phoenix All Suites West in 36542. | C35: https://www.brett-robinson.com/
A36: Harris Vacations | B36: Family-owned since 1983; focused luxury beach houses/homes (not mega condo inventory). Public rentals sitemap lists ~30 named homes. | C36: https://www.ourgulfshoresvacation.com/
A37: Liquid Life Vacation Rentals | B37: Public claim 800+ / 700+ properties coast-wide; Comparent snapshot ~218 Gulf Shores properties; resorts directory lists 50+ communities including many 36542 complexes. | C37: https://www.liquidlifevacationrentals.com/
A38: PMI Gulf Shores | B38: Local PMI franchise; vacation/short-term management; public direct-booking site exists but inventory not exhaustively scrapeable in this pass. | C38: https://www.gulfshoresvacationrentalmanagement.com/
A39: Vacasa (Seawind / Gulf Shores presence) | B39: National manager with public Seawind complex page; unit-level counts vary by date. | C39: https://www.vacasa.com/usa/Seawind-Condos-Gulf-Shores/
A40: Young's Suncoast | B40: Public complex pages for many GS buildings (Lighthouse, San Carlos, Crystal Shores West, Island Tower, Boardwalk, etc.). | C40: https://www.youngssuncoast.com/complexes/
A43: Illustrative 50-unit managed portfolio I/O
A44: Mix assumes realistic GS product: more 2BR inventory than 1BR/4BR. Uses IO Summary per-unit NOI & Inputs × unit counts.
A46: Scenario | B46: Units | C46: Inputs $/unit | D46: NOI $/unit | E46: Portfolio Inputs | F46: Portfolio NOI | G46: Blend I/O
A47: 1BR condo | B47: 6 | C47: 27688 | D47: 4688 | E47: =B47*C47 | F47: =B47*D47 | G47: =IF(C47=0,"n/a",D47/C47)
A48: 2BR gulf-view | B48: 12 | C48: 39028 | D48: 12648 | E48: =B48*C48 | F48: =B48*D48 | G48: =IF(C48=0,"n/a",D48/C48)
A49: 2BR gulf-front | B49: 16 | C49: 50410 | D49: 22040 | E49: =B49*C49 | F49: =B49*D49 | G49: =IF(C49=0,"n/a",D49/C49)
A50: 3BR gulf-front | B50: 10 | C50: 66298 | D50: 31528 | E50: =B50*C50 | F50: =B50*D50 | G50: =IF(C50=0,"n/a",D50/C50)
...

Sheet Assumptions
A1: Assumptions, Sources & Disclaimer
A3: Core definition
A4: I/O Ratio | B4: NOI ÷ Annual Cash Inputs
A5: NOI | B5: Gross Revenue − Annual Cash Inputs
A6: Gross Revenue | B6: ADR × Occupied Nights (owner-night personal use excluded from occupied nights)
A7: Annual Cash Inputs | B7: Mgmt fees + platform/OTA fees + HOA + insurance + owner utilities + maintenance/turnover + FF&E reserves + property tax. Does NOT include purchase price, closing costs, or mortgage principal.
A9: Market / pricing context
A10: Median sold | B10: ~$450K Gulf Shores 36542 (condo + SFH mix) — MARKET_GULF_SHORES_36542.md snapshot 2026
A11: Median ask | B11: ~$555K active inventory — ask-to-sold gap = buyer leverage
A12: VR mgmt fees | B12: Often 20–35% of gross on Alabama Gulf Coast
A13: Purchase prices | B13: Illustrative scenario anchors around/above median for gulf-front premiums; not comps
A14: ADR / nights | B14: Seasonal STR; peak summer/spring break/holidays — base case is blended annualized
A15: Property tax | B15: ~0.5% of purchase as Baldwin County–ish placeholder; verify parcel assessment
A16: Insurance | B16: Wind / flood / HO-6 or HO-3 — Gulf Coast premiums elevated; house >> condo
A17: HOA | B17: Condo dues vary widely by tower amenities/reserves; houses often $0
A18: Platform % | B18: 5% blended assumes partial direct-booking + residual OTA; Airbnb alone often higher
A19: Equity % | B19: 25% down for cash-on-cash illustration only — no debt service modeled
A20: Inventory | B20: 463 records from data/rentals_36542.json — 285 condo units, 100 complexes, 71 houses, 7 manager portfolios
A23: Disclaimer
A24: Illustrative educational model for Gulf Coast Estates internal / client conversation only. Not an appraisal, CMA, offering, tax advice, or guarantee of ADR, occupancy, NOI, or resale. Verify HOA rental rules, insurance quotes, tax assessments, and management contracts before any purchase. Public inventory scrape is incomplete vs full Airbnb/VRBO/MLS universe; manager coast-wide claims are not ZIP-36542 counts.
A28: Primary file sources
A29: data/rentals_36542.json | B29: 463-record public scrape inventory
A30: data/sources.md | B30: URL list + scrape date 2026-09-05
A31: MARKET_GULF_SHORES_36542.md | B31: Median sold ~$450K, VR fee band, competitor landscape
